Workbook
Name Title1: CashFlow[[#Headers],[Cash Flow]]
Name Title2: Income[[#Headers],[Monthly Income]]
Name Title3: Expenses[[#Headers],[Monthly expenses]]

Sheet Cash flow
C3: Year | E3: 2025
C4: Tot BUDGET
C8: Cash Flow | D8: Actual
C9: Total income | D9: ='Yearly income'!D10 -> 0
C10: Total expenses | D10: =Expenses[[#Totals],[Actual]] -> 0
C11: Evaluated Bank Amout | D11: =D9-D10 -> 0
D21: ='Yearly income'!$D$27 - 'Yearly expenses'!$D$42 -> 0
D22: ='Yearly income'!$D$38 - 'Yearly expenses'!$D$63 -> 0
D23: ='Yearly income'!$D$49 - 'Yearly expenses'!$D$84 -> 0
D24: ='Yearly income'!$D$60 - 'Yearly expenses'!$D$105 -> 0
D25: ='Yearly income'!$D$71 - 'Yearly expenses'!$D$126 -> 0
D26: ='Yearly income'!$D$82 - 'Yearly expenses'!$D$147 -> 0
D27: ='Yearly income'!$D$93 - 'Yearly expenses'!$D$168 -> 0
D28: ='Yearly income'!$D$104 - 'Yearly expenses'!$D$189 -> 0
D29: ='Yearly income'!$D$115 - 'Yearly expenses'!$D$210 -> 0
D30: ='Yearly income'!$D$126 - 'Yearly expenses'!$D$231 -> 0
D31: ='Yearly income'!$D$137 - 'Yearly expenses'!$D$252 -> 0
D32: ='Yearly income'!$D$148 - 'Yearly expenses'!$D$273 -> 0

Sheet Yearly income
C10: Yearly INCOME | D10: =SUM(D11:D15) -> 0
C11: PoliMi | D11: =SUM(D23+D34+D45) -> 0
C12: Deddo | D12: =SUM(D24+D35+D46) -> 0
C13: Other income | D13: =SUM(D25+D36+D47) -> 0
C14: Cash | D14: =SUM(D26+D37+D48) -> 0
C15: Init | D15: 0
C20: Janaury INCOME
C22: Monthly Income | D22: Actual
C23: PoliMi | D23: =SUMIFS('List Income'!$C$3:$C$100000, 'List Income'!$B$3:$B$100000, 'Yearly income'!$C11, 'List Income'!$A$3:$A$100000, ">=" & DATE('Cash flow'!$E$3, 1, 1), 'List Income'!$A$3:$A$100000, "<" & DATE('Cash flow'!$E$3, 2, 1)) -> 0
C24: Deddo | D24: =SUMIFS('List Income'!$C$3:$C$100000, 'List Income'!$B$3:$B$100000, 'Yearly income'!$C12, 'List Income'!$A$3:$A$100000, ">=" & DATE('Cash flow'!$E$3, 1, 1), 'List Income'!$A$3:$A$100000, "<" & DATE('Cash flow'!$E$3, 2, 1)) -> 0
C25: Other Income | D25: =SUMIFS('List Income'!$C$3:$C$100000, 'List Income'!$B$3:$B$100000, 'Yearly income'!$C13, 'List Income'!$A$3:$A$100000, ">=" & DATE('Cash flow'!$E$3, 1, 1), 'List Income'!$A$3:$A$100000, "<" & DATE('Cash flow'!$E$3, 2, 1)) -> 0
C26: Cash | D26: =SUMIFS('List Income'!$C$3:$C$100000, 'List Income'!$B$3:$B$100000, 'Yearly income'!$C14, 'List Income'!$A$3:$A$100000, ">=" & DATE('Cash flow'!$E$3, 1, 1), 'List Income'!$A$3:$A$100000, "<" & DATE('Cash flow'!$E$3, 2, 1)) -> 0
C27: Total Income | D27: =SUBTOTAL(109,Income[Actual]) -> 0
C31: February INCOME
C33: Monthly Income | D33: Actual
C34: PoliMi | D34: =SUMIFS('List Income'!$C$3:$C$100000, 'List Income'!$B$3:$B$100000, 'Yearly income'!$C11, 'List Income'!$A$3:$A$100000, ">=" & DATE('Cash flow'!$E$3, 2, 1), 'List Income'!$A$3:$A$100000, "<" & DATE('Cash flow'!$E$3, 3, 1)) -> 0
C35: Deddo | D35: =SUMIFS('List Income'!$C$3:$C$100000, 'List Income'!$B$3:$B$100000, 'Yearly income'!$C12, 'List Income'!$A$3:$A$100000, ">=" & DATE('Cash flow'!$E$3, 2, 1), 'List Income'!$A$3:$A$100000, "<" & DATE('Cash flow'!$E$3, 3, 1)) -> 0
C36: Other Income | D36: =SUMIFS('List Income'!$C$3:$C$100000, 'List Income'!$B$3:$B$100000, 'Yearly income'!$C13, 'List Income'!$A$3:$A$100000, ">=" & DATE('Cash flow'!$E$3, 2, 1), 'List Income'!$A$3:$A$100000, "<" & DATE('Cash flow'!$E$3, 3, 1)) -> 0
C37: Cash | D37: =SUMIFS('List Income'!$C$3:$C$100000, 'List Income'!$B$3:$B$100000, 'Yearly income'!$C14, 'List Income'!$A$3:$A$100000, ">=" & DATE('Cash flow'!$E$3, 2, 1), 'List Income'!$A$3:$A$100000, "<" & DATE('Cash flow'!$E$3, 3, 1)) -> 0
C38: Total Income | D38: =SUBTOTAL(109,Income18[Actual]) -> 0
C42: March INCOME
C44: Monthly Income | D44: Actual
C45: PoliMi | D45: =SUMIFS('List Income'!$C$3:$C$100000, 'List Income'!$B$3:$B$100000, 'Yearly income'!$C11, 'List Income'!$A$3:$A$100000, ">=" & DATE('Cash flow'!$E$3, 3, 1), 'List Income'!$A$3:$A$100000, "<" & DATE('Cash flow'!$E$3, 4, 1)) -> 0
C46: Deddo | D46: =SUMIFS('List Income'!$C$3:$C$100000, 'List Income'!$B$3:$B$100000, 'Yearly income'!$C12, 'List Income'!$A$3:$A$100000, ">=" & DATE('Cash flow'!$E$3, 3, 1), 'List Income'!$A$3:$A$100000, "<" & DATE('Cash flow'!$E$3, 4, 1)) -> 0
C47: Other Income | D47: =SUMIFS('List Income'!$C$3:$C$100000, 'List Income'!$B$3:$B$100000, 'Yearly income'!$C13, 'List Income'!$A$3:$A$100000, ">=" & DATE('Cash flow'!$E$3, 3, 1), 'List Income'!$A$3:$A$100000, "<" & DATE('Cash flow'!$E$3, 4, 1)) -> 0
C48: Cash | D48: =SUMIFS('List Income'!$C$3:$C$100000, 'List Income'!$B$3:$B$100000, 'Yearly income'!$C14, 'List Income'!$A$3:$A$100000, ">=" & DATE('Cash flow'!$E$3, 3, 1), 'List Income'!$A$3:$A$100000, "<" & DATE('Cash flow'!$E$3, 4, 1)) -> 0
C49: Total Income | D49: =SUBTOTAL(109,Income19[Actual]) -> 0
C53: April INCOME
C55: Monthly Income | D55: Actual
C56: PoliMi | D56: =SUMIFS('List Income'!$C$3:$C$100000, 'List Income'!$B$3:$B$100000, 'Yearly income'!$C22, 'List Income'!$A$3:$A$100000, ">=" & DATE('Cash flow'!$E$3, 4, 1), 'List Income'!$A$3:$A$100000, "<" & DATE('Cash flow'!$E$3, 5, 1)) -> 0
C57: Deddo | D57: =SUMIFS('List Income'!$C$3:$C$100000, 'List Income'!$B$3:$B$100000, 'Yearly income'!$C23, 'List Income'!$A$3:$A$100000, ">=" & DATE('Cash flow'!$E$3, 4, 1), 'List Income'!$A$3:$A$100000, "<" & DATE('Cash flow'!$E$3, 5, 1)) -> 0
C58: Other Income | D58: =SUMIFS('List Income'!$C$3:$C$100000, 'List Income'!$B$3:$B$100000, 'Yearly income'!$C24, 'List Income'!$A$3:$A$100000, ">=" & DATE('Cash flow'!$E$3, 4, 1), 'List Income'!$A$3:$A$100000, "<" & DATE('Cash flow'!$E$3, 5, 1)) -> 0
C59: Cash | D59: =SUMIFS('List Income'!$C$3:$C$100000, 'List Income'!$B$3:$B$100000, 'Yearly income'!$C25, 'List Income'!$A$3:$A$100000, ">=" & DATE('Cash flow'!$E$3, 4, 1), 'List Income'!$A$3:$A$100000, "<" & DATE('Cash flow'!$E$3, 5, 1)) -> 0
C60: Total Income | D60: =SUBTOTAL(109,Income197[Actual]) -> 0
C64: May INCOME
C66: Monthly Income | D66: Actual
C67: PoliMi | D67: =SUMIFS('List Income'!$C$3:$C$100000, 'List Income'!$B$3:$B$100000, 'Yearly income'!$C33, 'List Income'!$A$3:$A$100000, ">=" & DATE('Cash flow'!$E$3, 5, 1), 'List Income'!$A$3:$A$100000, "<" & DATE('Cash flow'!$E$3, 6, 1)) -> 0
C68: Deddo | D68: =SUMIFS('List Income'!$C$3:$C$100000, 'List Income'!$B$3:$B$100000, 'Yearly income'!$C34, 'List Income'!$A$3:$A$100000, ">=" & DATE('Cash flow'!$E$3, 5, 1), 'List Income'!$A$3:$A$100000, "<" & DATE('Cash flow'!$E$3, 6, 1)) -> 0
C69: Other Income | D69: =SUMIFS('List Income'!$C$3:$C$100000, 'List Income'!$B$3:$B$100000, 'Yearly income'!$C35, 'List Income'!$A$3:$A$100000, ">=" & DATE('Cash flow'!$E$3, 5, 1), 'List Income'!$A$3:$A$100000, "<" & DATE('Cash flow'!$E$3, 6, 1)) -> 0
C70: Cash | D70: =SUMIFS('List Income'!$C$3:$C$100000, 'List Income'!$B$3:$B$100000, 'Yearly income'!$C36, 'List Income'!$A$3:$A$100000, ">=" & DATE('Cash flow'!$E$3, 5, 1), 'List Income'!$A$3:$A$100000, "<" & DATE('Cash flow'!$E$3, 6, 1)) -> 0
...

Sheet Yearly expenses
C3: Yearly EXPENSES
C5: Monthly expenses | D5: Actual
C6: Restaurants | D6: =SUM(D28+D49+D70) -> 0
C7: Groceries | D7: =SUM(D29+D50+D71) -> 0
C8: Pre-paid card | D8: =SUM(D30+D51+D72) -> 0
C9: Going out | D9: =SUM(D31+D52+D73) -> 0
C10: Claudia | D10: =SUM(D32+D53+D74) -> 0
C11: Family | D11: =SUM(D33+D54+D75) -> 0
C12: Shopping | D12: =SUM(D34+D55+D76) -> 0
C13: Transportation | D13: =SUM(D35+D56+D77) -> 0
C14: Personal care | D14: =SUM(D36+D57+D78) -> 0
C15: Credit cards | D15: =SUM(D37+D58+D79) -> 0
C16: Gifts / Charity | D16: =SUM(D38+D59+D80) -> 0
C17: Travel | D17: =SUM(D39+D60+D81) -> 0
... C19: Other | D19: =SUM(D41+D62+D83) -> 0
C20: Total expenses | D20: =SUBTOTAL(109,Expenses[Actual]) -> 0
C25: January EXPENSES
C27: Monthly expenses | D27: Actual
C28: Restaurants | D28: =SUMIFS('List Expenses'!$C$3:$C$100000, 'List Expenses'!$B$3:$B$100000, 'Yearly expenses'!$C6, 'List Expenses'!$A$3:$A$100000, ">=" & DATE('Cash flow'!$E$3, 1, 1), 'List Expenses'!$A$3:$A$100000, "<" & DATE('Cash flow'!$E$3, 2, 1)) -> 0
C29: Groceries | D29: =SUMIFS('List Expenses'!$C$3:$C$100000, 'List Expenses'!$B$3:$B$100000, 'Yearly expenses'!$C7, 'List Expenses'!$A$3:$A$100000, ">=" & DATE('Cash flow'!$E$3, 1, 1), 'List Expenses'!$A$3:$A$100000, "<" & DATE('Cash flow'!$E$3, 2, 1)) -> 0
C30: Pre-paid card | D30: =SUMIFS('List Expenses'!$C$3:$C$100000, 'List Expenses'!$B$3:$B$100000, 'Yearly expenses'!$C8, 'List Expenses'!$A$3:$A$100000, ">=" & DATE('Cash flow'!$E$3, 1, 1), 'List Expenses'!$A$3:$A$100000, "<" & DATE('Cash flow'!$E$3, 2, 1)) -> 0
C31: Going out | D31: =SUMIFS('List Expenses'!$C$3:$C$100000, 'List Expenses'!$B$3:$B$100000, 'Yearly expenses'!$C9, 'List Expenses'!$A$3:$A$100000, ">=" & DATE('Cash flow'!$E$3, 1, 1), 'List Expenses'!$A$3:$A$100000, "<" & DATE('Cash flow'!$E$3, 2, 1)) -> 0
C32: Claudia | D32: =SUMIFS('List Expenses'!$C$3:$C$100000, 'List Expenses'!$B$3:$B$100000, 'Yearly expenses'!$C10, 'List Expenses'!$A$3:$A$100000, ">=" & DATE('Cash flow'!$E$3, 1, 1), 'List Expenses'!$A$3:$A$100000, "<" & DATE('Cash flow'!$E$3, 2, 1)) -> 0
C33: Family | D33: =SUMIFS('List Expenses'!$C$3:$C$100000, 'List Expenses'!$B$3:$B$100000, 'Yearly expenses'!$C11, 'List Expenses'!$A$3:$A$100000, ">=" & DATE('Cash flow'!$E$3, 1, 1), 'List Expenses'!$A$3:$A$100000, "<" & DATE('Cash flow'!$E$3, 2, 1)) -> 0
C34: Shopping | D34: =SUMIFS('List Expenses'!$C$3:$C$100000, 'List Expenses'!$B$3:$B$100000, 'Yearly expenses'!$C12, 'List Expenses'!$A$3:$A$100000, ">=" & DATE('Cash flow'!$E$3, 1, 1), 'List Expenses'!$A$3:$A$100000, "<" & DATE('Cash flow'!$E$3, 2, 1)) -> 0
C35: Transportation | D35: =SUMIFS('List Expenses'!$C$3:$C$100000, 'List Expenses'!$B$3:$B$100000, 'Yearly expenses'!$C13, 'List Expenses'!$A$3:$A$100000, ">=" & DATE('Cash flow'!$E$3, 1, 1), 'List Expenses'!$A$3:$A$100000, "<" & DATE('Cash flow'!$E$3, 2, 1)) -> 0
C36: Personal care | D36: =SUMIFS('List Expenses'!$C$3:$C$100000, 'List Expenses'!$B$3:$B$100000, 'Yearly expenses'!$C14, 'List Expenses'!$A$3:$A$100000, ">=" & DATE('Cash flow'!$E$3, 1, 1), 'List Expenses'!$A$3:$A$100000, "<" & DATE('Cash flow'!$E$3, 2, 1)) -> 0
C37: Credit cards | D37: =SUMIFS('List Expenses'!$C$3:$C$100000, 'List Expenses'!$B$3:$B$100000, 'Yearly expenses'!$C15, 'List Expenses'!$A$3:$A$100000, ">=" & DATE('Cash flow'!$E$3, 1, 1), 'List Expenses'!$A$3:$A$100000, "<" & DATE('Cash flow'!$E$3, 2, 1)) -> 0
C38: Gifts / Charity | D38: =SUMIFS('List Expenses'!$C$3:$C$100000, 'List Expenses'!$B$3:$B$100000, 'Yearly expenses'!$C16, 'List Expenses'!$A$3:$A$100000, ">=" & DATE('Cash flow'!$E$3, 1, 1), 'List Expenses'!$A$3:$A$100000, "<" & DATE('Cash flow'!$E$3, 2, 1)) -> 0
C39: Travel | D39: =SUMIFS('List Expenses'!$C$3:$C$100000, 'List Expenses'!$B$3:$B$100000, 'Yearly expenses'!$C17, 'List Expenses'!$A$3:$A$100000, ">=" & DATE('Cash flow'!$E$3, 1, 1), 'List Expenses'!$A$3:$A$100000, "<" & DATE('Cash flow'!$E$3, 2, 1)) -> 0
... C41: Other | D41: =SUMIFS('List Expenses'!$C$3:$C$100000, 'List Expenses'!$B$3:$B$100000, 'Yearly expenses'!$C19, 'List Expenses'!$A$3:$A$100000, ">=" & DATE('Cash flow'!$E$3, 1, 1), 'List Expenses'!$A$3:$A$100000, "<" & DATE('Cash flow'!$E$3, 2, 1)) -> 0
C42: Total expenses | D42: =SUBTOTAL(109,Expenses2[Actual]) -> 0
C46: February EXPENSES
C48: Monthly expenses | D48: Actual
C49: Restaurants | D49: =SUMIFS('List Expenses'!$C$3:$C$100000, 'List Expenses'!$B$3:$B$100000, 'Yearly expenses'!$C6, 'List Expenses'!$A$3:$A$100000, ">=" & DATE('Cash flow'!$E$3, 2, 1), 'List Expenses'!$A$3:$A$100000, "<" & DATE('Cash flow'!$E$3, 3, 1)) -> 0
C50: Groceries | D50: =SUMIFS('List Expenses'!$C$3:$C$100000, 'List Expenses'!$B$3:$B$100000, 'Yearly expenses'!$C7, 'List Expenses'!$A$3:$A$100000, ">=" & DATE('Cash flow'!$E$3, 2, 1), 'List Expenses'!$A$3:$A$100000, "<" & DATE('Cash flow'!$E$3, 3, 1)) -> 0
C51: Pre-paid card | D51: =SUMIFS('List Expenses'!$C$3:$C$100000, 'List Expenses'!$B$3:$B$100000, 'Yearly expenses'!$C8, 'List Expenses'!$A$3:$A$100000, ">=" & DATE('Cash flow'!$E$3, 2, 1), 'List Expenses'!$A$3:$A$100000, "<" & DATE('Cash flow'!$E$3, 3, 1)) -> 0
C52: Going out | D52: =SUMIFS('List Expenses'!$C$3:$C$100000, 'List Expenses'!$B$3:$B$100000, 'Yearly expenses'!$C9, 'List Expenses'!$A$3:$A$100000, ">=" & DATE('Cash flow'!$E$3, 2, 1), 'List Expenses'!$A$3:$A$100000, "<" & DATE('Cash flow'!$E$3, 3, 1)) -> 0
C53: Claudia | D53: =SUMIFS('List Expenses'!$C$3:$C$100000, 'List Expenses'!$B$3:$B$100000, 'Yearly expenses'!$C10, 'List Expenses'!$A$3:$A$100000, ">=" & DATE('Cash flow'!$E$3, 2, 1), 'List Expenses'!$A$3:$A$100000, "<" & DATE('Cash flow'!$E$3, 3, 1)) -> 0
C54: Family | D54: =SUMIFS('List Expenses'!$C$3:$C$100000, 'List Expenses'!$B$3:$B$100000, 'Yearly expenses'!$C11, 'List Expenses'!$A$3:$A$100000, ">=" & DATE('Cash flow'!$E$3, 2, 1), 'List Expenses'!$A$3:$A$100000, "<" & DATE('Cash flow'!$E$3, 3, 1)) -> 0
...

Sheet List Income
A1: DATE | B1: CATEGORY | C1: AMOUT | D1: DESCRIPTION

Sheet List Expenses
A1: DATE | B1: CATEGORY | C1: AMOUNT | D1: DESCRIPTION
